File: testFiles/auger.vms
VAMAS Surface Chemical Analysis Standard Data Transfer Format 1988 May 4
Not specified
MI-600-BE9240AA
DESKTOP-MI6NA2R\kratos
20200220_PK_Cu_AES.experiment
4
Casa Info Follows CasaXPS Version 2.3.22PR1.0
0
SourceAnalyserAngle: Not Specified
CasaRowLabel:PK_Cu_AES
NORM
REGULAR
1
4
Index
d
PositionX [mm]
n
PositionY [mm]
n
PositionZ [mm]
n
0
0
0
0
4
Survey
PK_Cu_AES
2020
2
20
13
9
24
1
39
Casa Info Follows
0
0
0
0
Creation
Created by : DESKTOP-MI6NA2R\kratos
Date created : 20/02/2020 13:09
Computer : DESKTOP-MI6NA2R
Location
Location ID : 1: PK_Cu_AES
Sample : PK_Cu_AES
Description : (43.434,6.505,-2.973)mm
Tilt : 0.00
Charge Neutraliser : Off
Settings
Excitation
Mode : FEG Electron Gun
Tuning : 10 keV
Spot size : 0
Anode library : AES
ESCA modes
Collimation : AES
Lens : AES
Resolution : 3.00
Scan
Deflection : (0.000, 0.000)mm
Survey : 20.000-3000.000eV, Sweeps 2
Start : 20.000eV
End : 3000.000eV
Centre : 1510.000eV
Width : 2980.000eV
Step size : 1.000eV
Number Steps : 2980
Dwell time : 101ms
Sweep time : 300s
Sweeps : 2
Instrument Conditions
Work function : -4.50
XPS
1
43.434
6.50523
-2.9731
Not specified
0
1e+037
1e+037
1e+037
1e+037
1e+037
FAT
3
1e+037
-4.5
1e+037
1e+037
1e+037
1e+037
1e+037
Survey

-1
Kinetic energy
eV
20
1
2
Intensity
d
Transmission
d
pulse counting
0.100637
1e+037
37146
293846
226768
256328
235576
192202
184915
176875
159261
146702
140311
135402
126214
119769
113927
110503
109907
109632
105536
104027
102679
104074
104215
97161
91423
87563
83730
82270
81618
80269
78860
76906
75129
73454
71287
70355
68245
67668
67138
66394
65263
64837
65142
65020
64357
63521
63090
62926
61793
61085
60169
59410
59736
59139
58722
57895
57168
56924
56932
56955
55980
54667
54487
54860
55025
54953
54281
53665
53185
52995
53539
52373
51067
50487
50676
50291
49928
49054
47687
47643
46611
46342
46121
45684
44810
44976
43934
43981
43453
42952
42724
42954
42669
42211
42207
41920
41927
41806
41776
41380
41556
41781
41857
42130
42290
42343
42360
42622
42459
42819
42761
43067
43327
43369
43361
44092
44062
44840
44992
45582
45420
45161
45222
44857
44513
44076
43726
42467
42163
41859
41541
41258
41268
41198
41198
41107
41059
41127
40849
41023
40621
41080
41312
41245
40837
40764
40685
40562
40215
40833
40469
40642
40216
40539
40306
40146
40284
39892
40354
39937
40203
40478
40033
40171
40041
39763
39662
39395
39527
39235
39474
39270
39116
39082
38824
38971
38523
38355
38560
38555
38357
37871
38400
38086
38094
38133
37912
37936
37813
37789
38129
37851
37724
37567
37296
37984
37649
37413
37462
37546
37408
37442
37580
37213
37271
37231
37518
37543
37309
37739
37644
37800
37677
37493
38105
38179
38550
39061
38968
39141
39206
39669
40154
39659
39812
39962
40322
40605
40896
41175
41302
41326
42542
42983
43506
43987
43815
44009
43890
44210
44630
44986
45430
46782
48310
49275
50064
48506
46892
45798
45156
44571
44215
44096
44308
44470
44497
45045
45473
45878
45850
46035
45814
45619
45737
44908
44901
44389
43709
43005
42952
42451
42132
42511
41874
42032
41892
41921
41885
42031
41993
42135
42042
41620
41623
41783
41678
42096
41742
41843
41856
41813
42094
42501
42466
42666
42748
42761
42920
43089
43344
43423
43416
43446
43675
43672
43894
43772
43781
43963
44192
44118
43987
44036
43860
44377
44288
44258
43761
43740
44132
43902
43702
43740
43738
43646
43627
43523
43587
43576
43403
43194
43058
43240
42799
42722
43194
43044
43068
43150
43747
43102
43629
43492
44185
43868
44161
44695
44511
45093
44826
45299
45587
45733
45864
46485
46811
46824
47212
47412
47872
47068
48001
48441
49240
49468
49518
49796
50215
50911
51452
51072
52010
52250
52626
52188
51941
51869
51716
51552
50680
50342
50288
50263
50545
49956
49842
50320
49982
50270
49734
49991
49585
49973
50028
50026
50563
50644
50453
50724
50772
50764
51468
50947
51761
52242
52516
52306
53304
53860
54301
53350
52202
52404
52213
51287
50121
49525
49159
49237
49444
49198
48405
48090
48209
48130
48260
48315
48475
48484
48594
48888
48984
49198
49707
49687
49880
50714
50355
50558
50682
50641
50922
51356
52153
52673
53158
55266
56652
58959
59348
55101
50106
47768
47302
46857
46748
46549
47422
47353
46845
46229
45168
44868
44516
44696
44549
44822
44768
45100
45004
45189
45247
45715
45118
45697
45482
45796
45696
45743
45699
45827
46008
46270
46642
46176
45949
46522
46523
46692
46784
46592
46984
46773
47097
47360
47051
47205
47532
46623
47405
47110
47730
47242
47377
47717
47355
47880
47844
47925
47664
47958
48048
48024
48185
47991
48247
48185
48645
48255
48480
48533
49087
49014
48938
49263
49041
49156
49240
49309
49725
49428
49826
49889
49886
49945
50276
50375
50213
50303
50377
50703
51114
51121
51229
51032
51295
51422
51646
51483
51721
51894
52242
52080
51926
52076
52284
52398
52383
52740
52594
52544
52549
52794
52812
52881
52840
53266
53193
53151
53224
53086
53277
53459
53300
53299
53598
53450
53352
53601
53802
53764
53375
53714
54051
53515
53548
53329
53487
53598
53723
53440
53701
53822
53694
53698
53543
53420
52988
53333
53609
52877
52786
53305
53222
52854
52979
53504
52896
53028
52906
52703
52968
52446
52834
52455
52367
52235
52117
51978
52035
51829
51640
51596
51872
51391
51600
51302
51104
51149
51124
50763
50906
50827
50503
50697
50569
50818
50388
50489
50597
50590
50027
50473
50307
50260
49916
50244
49919
50126
50109
49882
49890
49897
49744
50018
49823
49622
49861
49714
49837
49460
49823
49741
49326
49563
49861
49611
49722
49861
50157
49779
49490
49709
49781
49889
50033
50295
50342
49683
49766
50018
50157
50451
49976
50428
50512
50106
50210
50213
50572
50786
50950
50632
50796
50599
50864
51078
51143
50936
51305
51454
51650
51527
51873
52115
52013
51669
52005
52428
51952
52076
52409
52555
52468
52646
52780
53103
52806
53254
53425
53405
53391
53323
53660
53954
53803
53484
53941
53880
54467
54730
54095
54668
54493
54494
54785
54725
54985
54904
55331
55835
55388
55708
55643
55820
55809
55885
55720
56536
56229
56503
56389
56544
56887
56622
57015
56920
56939
57256
57332
57496
57698
57682
57797
57888
57708
57880
58141
58334
57776
58455
58464
59247
58784
58676
58810
58981
59046
59005
59618
58940
59424
59518
59018
59957
59686
60470
60119
60445
60348
60644
60788
60693
61580
61052
61663
61494
61544
61242
61593
61603
61887
61621
62027
61853
62048
62230
62471
62843
62672
62830
62636
62696
62971
63317
63053
63467
63124
63288
63145
63151
64068
63671
63858
64067
64338
64063
64259
64363
64519
64562
64509
64822
64928
65099
65436
65351
64846
65376
65301
65319
65746
66165
65751
66076
66100
66246
66461
66543
66766
66602
66499
66686
66524
66903
66803
66826
66979
67176
67526
67284
67425
67374
68309
67472
67898
67954
68564
68256
68127
68275
68558
68633
68245
68860
68981
69022
69303
69493
69107
69248
69479
69160
69527
69609
69605
69415
69662
70052
70496
70181
70176
70280
70663
70402
70601
70486
70955
70817
70592
70872
71206
70789
71227
71230
71117
71371
71595
71304
71437
71458
71830
71639
71713
72170
71960
72244
72127
72970
72387
72374
72366
72354
72497
72697
73103
72526
73437
72795
73062
73227
73543
73312
73405
73363
73956
73565
73721
74136
73662
73877
73947
73576
73895
74540
74160
74540
74342
74404
74526
74508
74257
74833
74691
74419
75249
75334
74888
75314
75416
74846
75660
75561
75652
75307
75776
75660
75705
75921
76515
75643
76135
75990
76123
76334
75920
75826
76760
76393
77043
76848
76406
76585
76532
76608
76698
77117
76948
77524
76907
77016
76957
77439
77666
77470
77152
77491
77466
77497
77416
77810
78110
77286
77917
77920
78156
78342
77860
77662
77954
78301
77719
78811
78531
78332
78652
78434
78437
79182
79049
78475
79098
78760
79229
79254
79225
79436
79185
78957
79483
79493
79464
79845
79784
79946
79606
79935
79915
79762
79932
80342
79556
80407
80364
80577
80209
80693
80734
80647
80668
80681
81079
80672
81268
81427
80787
81328
81179
81673
81436
81357
82177
81541
81460
81605
81798
81861
82378
81744
82459
82228
82353
82131
82214
82273
82159
82368
82818
82757
82529
82943
82697
83289
83165
83003
83091
83417
83414
83304
83739
83790
83437
83599
83692
83682
84090
83984
84304
83897
83695
84224
84543
84366
84620
84164
84464
84821
84544
84572
85149
85064
85118
84724
84651
85158
85310
85151
85333
85598
86049
85407
85747
85353
85959
85871
85832
85853
86102
86614
86359
86894
86697
87120
86404
86361
86432
87019
86562
86801
87370
87267
87486
87282
87416
87583
87831
88016
87226
87514
87707
87668
87795
87805
88192
87923
88213
88236
88041
88382
88770
88542
88525
88509
88035
88659
88930
88784
89354
89415
89643
89385
89350
89197
89748
89758
90189
89602
90473
90214
89967
90346
90427
90250
90198
90777
91128
89770
90997
90722
91364
90627
90970
90686
91269
91131
91814
91640
91607
91471
91980
91927
91921
91767
92325
92026
91862
92242
92447
93015
92787
92702
92629
92798
93121
92730
93391
93101
93461
93232
93589
93553
93449
93636
93723
93889
94375
94392
94070
94129
94001
94509
94210
94571
94529
94721
94726
95145
95313
94761
95525
95132
95423
95029
95536
95523
95107
95585
95596
95670
96227
95701
95865
95758
96358
96343
96558
96227
96461
96833
97428
96773
97117
97006
97169
96782
96900
97493
97047
96761
97526
97941
97425
97572
98769
97783
98338
98455
98652
98352
98670
98605
98242
99142
98713
99088
98668
99137
99026
99231
100074
99739
99965
99456
99695
99488
99810
99892
100414
100313
100736
100615
100882
100874
101215
101243
100864
101098
101482
101054
101589
101299
101401
101372
101647
101997
101808
102415
102285
101754
102272
102930
101955
102533
103342
102926
102672
103203
102978
103482
103183
103729
103863
103625
103796
103433
103816
103395
103696
104013
104364
104351
103956
104325
104320
104275
105241
105536
104854
105061
105466
105375
105782
105209
105571
105604
105665
105752
105874
106191
106411
106558
106939
106662
106593
107247
106627
106693
106626
107510
106799
107780
107044
107442
107453
108157
107951
107898
107789
108884
108208
108330
109101
109008
108626
109273
109207
109164
109123
109484
109667
109750
109671
109738
110043
109729
110120
109705
110292
110383
110422
110652
110812
110742
110706
111032
111019
111424
111574
111340
112224
111793
112131
112222
111871
112669
112602
112565
112713
112951
112772
113340
113051
113602
113399
113939
113761
114617
114319
114152
114283
114059
115230
114940
114510
114441
115147
115306
116009
115579
115922
116562
116453
116287
115951
116322
116331
116853
116883
116762
117303
117836
117497
117689
117656
118348
118470
118278
117917
118783
118727
119329
118969
119526
119582
119282
119468
119368
119149
119953
120177
119738
120159
120009
120058
120619
121147
120716
121665
121357
121487
121407
121958
121701
121447
122156
122368
122194
122781
122218
122503
123018
1
1: C KLL
PK_Cu_AES
2020
2
20
13
31
23
1
42
Casa Info Follows
0
0
0
0
Creation
Created by : DESKTOP-MI6NA2R\kratos
Date created : 20/02/2020 13:31
Computer : DESKTOP-MI6NA2R
Location
Location ID : 1: PK_Cu_AES
Sample : PK_Cu_AES
Description : (43.434,6.505,-2.973)mm
Tilt : 0.00
Charge Neutraliser : Off
Settings
Excitation
Mode : FEG Electron Gun
Tuning : 10 keV
Spot size : 0
Anode library : AES
ESCA modes
Collimation : AES
Lens : AES
Resolution : 3.00
Scan
Deflection : (0.000, 0.000)mm
C KLL : 200.000-300.000eV, Sweeps 5
Start : 200.000eV
End : 300.000eV
Centre : 250.000eV
Width : 100.000eV
Step size : 0.200eV
Number Steps : 500
Dwell time : 359ms
Sweep time : 180s
Sweeps : 5
Target quality : 200
Instrument Conditions
Work function : -4.50
Acquisition Conditions
Quality : 82.12
XPS
2
43.434
6.50523
-2.9731
Not specified
0
1e+037
1e+037
1e+037
1e+037
1e+037
FAT
3
1e+037
-4.5
1e+037
1e+037
1e+037
1e+037
1e+037
C
KLL
-1
Kinetic energy
eV
200
0.2
2
Intensity
d
Transmission
d
pulse counting
0.359281
5
0
1e+037
1e+037
1e+037
0
1002
226495
252397
1
1
252397
1
251580
1
252224
1
251673
1
251165
1
251694
1
250931
1
251642
1
251268
1
251624
1
250967
1
250216
1
250659
1
250242
1
250190
1
249955
1
249379
1
248445
1
248563
1
249066
1
248482
1
248975
1
248623
1
248178
1
247835
1
247917
1
248019
1
248080
1
247308
1
247790
1
247946
1
247024
1
247999
1
247661
1
247983
1
247132
1
247379
1
246905
1
247208
1
247718
1
246985
1
246978
1
247491
1
247216
1
247636
1
247828
1
247324
1
247455
1
247598
1
246857
1
247404
1
248137
1
248223
1
248160
1
247502
1
248613
1
247721
1
247962
1
247569
1
247934
1
247966
1
248406
1
248553
1
247803
1
247791
1
247813
1
248393
1
247621
1
247493
1
247200
1
247653
1
246884
1
246700
1
247302
1
247911
1
246724
1
246985
1
247610
1
247584
1
247572
1
247315
1
247124
1
246842
1
247763
1
246598
1
246606
1
246728
1
247084
1
247298
1
246441
1
245821
1
246636
1
246373
1
246174
1
245851
1
246481
1
246657
1
246202
1
245543
1
245577
1
245530
1
246029
1
245614
1
245058
1
245452
1
245715
1
245263
1
245134
1
245204
1
245084
1
245282
1
245392
1
245012
1
244687
1
244307
1
244644
1
244930
1
245184
1
245207
1
244858
1
245065
1
245101
1
244674
1
244595
1
244245
1
244788
1
244508
1
244252
1
244666
1
244287
1
244421
1
243994
1
244574
1
245284
1
244962
1
244541
1
243762
1
243476
1
243752
1
244266
1
243108
1
243355
1
244019
1
243265
1
243930
1
243543
1
243861
1
243891
1
244486
1
243513
1
243436
1
243758
1
243554
1
243529
1
243878
1
243622
1
242984
1
242404
1
243589
1
243085
1
242673
1
242622
1
242584
1
243242
1
243597
1
243604
1
243556
1
242403
1
242629
1
243120
1
243412
1
243666
1
243341
1
243445
1
242767
1
242961
1
242743
1
243039
1
243178
1
243220
1
243087
1
242985
1
242748
1
242469
1
242778
1
243115
1
243154
1
243502
1
243548
1
244224
1
244199
1
243838
1
243129
1
243783
1
243715
1
243726
1
243688
1
243691
1
243648
1
243520
1
243114
1
243304
1
244287
1
243559
1
243165
1
243878
1
243913
1
243839
1
243933
1
243044
1
243839
1
243407
1
243419
1
243563
1
243394
1
243034
1
243860
1
243559
1
243514
1
243203
1
243560
1
243219
1
243529
1
243215
1
243509
1
242897
1
243280
1
243501
1
243273
1
243160
1
242928
1
242844
1
242894
1
242257
1
243173
1
242367
1
243572
1
243684
1
242709
1
242493
1
243313
1
243292
1
243018
1
242805
1
243585
1
242526
1
243330
1
243536
1
243104
1
242668
1
243642
1
243796
1
243379
1
243042
1
242728
1
242972
1
242833
1
243271
1
243972
1
244360
1
243650
1
243220
1
243402
1
243647
1
244428
1
244506
1
244062
1
243958
1
243724
1
243808
1
244486
1
244346
1
244362
1
245146
1
244784
1
244885
1
245026
1
244698
1
245278
1
244832
1
244411
1
244826
1
245197
1
244682
1
244865
1
245233
1
244552
1
244141
1
244887
1
245422
1
244473
1
244747
1
244588
1
244252
1
244620
1
244786
1
244211
1
244294
1
244659
1
244291
1
244948
1
244576
1
244654
1
244579
1
244208
1
243565
1
243763
1
243681
1
243503
1
243999
1
243432
1
243070
1
243829
1
243643
1
242960
1
243127
1
243228
1
243625
1
242640
1
242923
1
242385
1
242271
1
242539
1
242773
1
241876
1
241757
1
242714
1
242082
1
242316
1
242071
1
241001
1
241091
1
240410
1
240496
1
240241
1
240493
1
239675
1
239514
1
239233
1
238824
1
238986
1
239167
1
239462
1
239506
1
238296
1
237870
1
237921
1
237390
1
237383
1
236738
1
236775
1
236544
1
236099
1
235383
1
235244
1
235757
1
235800
1
235089
1
234775
1
233776
1
234731
1
234368
1
233852
1
233515
1
233122
1
232800
1
232901
1
232789
1
233075
1
232861
1
232824
1
232528
1
232272
1
232172
1
231431
1
231326
1
231496
1
231757
1
231280
1
230709
1
230617
1
231457
1
230793
1
230696
1
230112
1
230036
1
230226
1
229995
1
230374
1
229882
1
229927
1
230324
1
229173
1
228912
1
229041
1
229336
1
229547
1
229469
1
228251
1
229458
1
229405
1
228163
1
228351
1
228814
1
228585
1
228463
1
228627
1
228816
1
228542
1
228365
1
229153
1
228722
1
228772
1
227734
1
227299
1
227570
1
227502
1
228077
1
227818
1
228082
1
227190
1
228021
1
227159
1
227151
1
227305
1
226944
1
226633
1
227431
1
227576
1
227960
1
227308
1
227545
1
227459
1
226713
1
227302
1
226973
1
227399
1
227319
1
227632
1
227217
1
227990
1
226964
1
227002
1
227548
1
226781
1
227748
1
227331
1
227073
1
226861
1
226767
1
227821
1
227781
1
227459
1
226880
1
226495
1
226999
1
227060
1
227476
1
228774
1
227987
1
227081
1
227683
1
227165
1
227306
1
227229
1
227314
1
227090
1
226541
1
227774
1
227880
1
227033
1
227112
1
227697
1
227538
1
227354
1
227821
1
227523
1
228160
1
227658
1
227776
1
227368
1
227157
1
227672
1
227596
1
227799
1
227767
1
227286
1
227140
1
227253
1
226995
1
227165
1
227222
1
227771
1
227349
1
227655
1
227983
1
228004
1
227739
1
226764
1
227786
1
228245
1
O KLL
PK_Cu_AES
2020
2
20
13
31
23
1
42
Casa Info Follows
0
0
0
0
Creation
Created by : DESKTOP-MI6NA2R\kratos
Date created : 20/02/2020 13:31
Computer : DESKTOP-MI6NA2R
Location
Location ID : 1: PK_Cu_AES
Sample : PK_Cu_AES
Description : (43.434,6.505,-2.973)mm
Tilt : 0.00
Charge Neutraliser : Off
Settings
Excitation
Mode : FEG Electron Gun
Tuning : 10 keV
Spot size : 0
Anode library : AES
ESCA modes
Collimation : AES
Lens : AES
Resolution : 3.00
Scan
Deflection : (0.000, 0.000)mm
O KLL : 440.600-570.400eV, Sweeps 5
Start : 440.600eV
End : 570.400eV
Centre : 505.500eV
Width : 129.800eV
Step size : 0.200eV
Number Steps : 649
Dwell time : 277ms
Sweep time : 180s
Sweeps : 5
Target quality : 200
Instrument Conditions
Work function : -4.50
Acquisition Conditions
Quality : 103.10
XPS
3
43.434
6.50523
-2.9731
Not specified
0
1e+037
1e+037
1e+037
1e+037
1e+037
FAT
3
1e+037
-4.5
1e+037
1e+037
1e+037
1e+037
1e+037
O
KLL
-1
Kinetic energy
eV
440.6
0.2
2
Intensity
d
Transmission
d
pulse counting
0.276923
5
0
1e+037
1e+037
1e+037
0
1300
185105
215747
1
1
187519
1
187077
1
187039
1
186483
1
187263
1
187775
1
187020
1
187113
1
187257
1
187820
1
187381
1
186757
1
187185
1
187528
1
187541
1
188124
1
187409
1
187566
1
187517
1
187081
1
187244
1
187666
1
188744
1
187647
1
187288
1
187868
1
187552
1
187894
1
187854
1
187798
1
187667
1
187430
1
187250
1
187644
1
187501
1
188317
1
188522
1
188057
1
188041
1
188143
1
187897
1
188645
1
188126
1
188155
1
188611
1
188601
1
188782
1
188119
1
188156
1
188269
1
188090
1
187834
1
187408
1
187834
1
188649
1
188795
1
188732
1
188351
1
188778
1
188310
1
188644
1
188345
1
188702
1
188806
1
188926
1
189013
1
188163
1
188690
1
188812
1
188701
1
188294
1
188858
1
189534
1
189503
1
188871
1
188406
1
188293
1
188581
1
188572
1
189050
1
188920
1
188622
1
188756
1
188587
1
189010
1
189037
1
189496
1
189243
1
189979
1
189705
1
189453
1
189505
1
189553
1
189436
1
190174
1
190037
1
190306
1
189711
1
190216
1
189798
1
190121
1
190518
1
190324
1
190988
1
190617
1
190725
1
190325
1
190845
1
190630
1
190289
1
189938
1
190533
1
190468
1
190808
1
191253
1
191734
1
191779
1
191196
1
191332
1
191525
1
191919
1
191713
1
192196
1
191797
1
192749
1
192110
1
192474
1
192239
1
192770
1
192771
1
192961
1
192869
1
192709
1
193265
1
193567
1
193188
1
194076
1
194036
1
193618
1
193720
1
194051
1
193761
1
194363
1
194211
1
194023
1
193813
1
194314
1
193918
1
194201
1
194095
1
194616
1
195059
1
194719
1
194678
1
195139
1
194588
1
194842
1
195107
1
194641
1
194631
1
194806
1
195352
1
195669
1
195047
1
195543
1
194756
1
195266
1
194893
1
195017
1
195091
1
195635
1
195451
1
195482
1
195344
1
195218
1
196059
1
195819
1
195556
1
195643
1
195372
1
195734
1
196021
1
195373
1
196092
1
195788
1
195318
1
195862
1
195992
1
195446
1
195894
1
195670
1
195680
1
196456
1
196130
1
196339
1
196420
1
197220
1
196188
1
196663
1
196562
1
197065
1
196407
1
196663
1
196739
1
197050
1
197291
1
197869
1
197769
1
198111
1
197807
1
197980
1
198412
1
197657
1
198366
1
199288
1
198535
1
199772
1
199592
1
199969
1
200486
1
200316
1
200275
1
200992
1
200502
1
200388
1
201457
1
201386
1
201021
1
201505
1
201552
1
201238
1
201758
1
201471
1
200883
1
200874
1
200820
1
200735
1
200891
1
200501
1
200967
1
200640
1
200405
1
200864
1
200543
1
200466
1
200773
1
200557
1
200027
1
200664
1
200731
1
200752
1
200310
1
200278
1
200448
1
200067
1
199634
1
199828
1
199988
1
199891
1
199870
1
199705
1
199652
1
199730
1
199366
1
199367
1
198960
1
198357
1
198469
1
199140
1
198835
1
198551
1
198084
1
198138
1
199016
1
199353
1
199671
1
199237
1
199041
1
198745
1
199448
1
199338
1
199701
1
199408
1
199026
1
199549
1
199567
1
199586
1
199827
1
200665
1
199696
1
199483
1
199909
1
199619
1
199596
1
200103
1
200892
1
200779
1
200740
1
201283
1
201409
1
200937
1
202077
1
202001
1
201715
1
202496
1
202798
1
203677
1
203498
1
204305
1
204209
1
204785
1
205451
1
205125
1
205339
1
206050
1
206895
1
207687
1
208732
1
209575
1
208632
1
209584
1
210337
1
210458
1
211146
1
211749
1
211965
1
212290
1
212495
1
213037
1
213915
1
213800
1
213850
1
214222
1
214520
1
214772
1
214445
1
215085
1
215747
1
215208
1
214909
1
213794
1
213909
1
214548
1
214076
1
214484
1
213621
1
213037
1
212359
1
212317
1
212350
1
211316
1
210733
1
210145
1
209496
1
209203
1
208473
1
207370
1
206093
1
204669
1
205629
1
204130
1
203139
1
201032
1
201380
1
201286
1
200567
1
200666
1
199016
1
198406
1
197725
1
196977
1
196985
1
196218
1
195612
1
195417
1
195221
1
194820
1
194548
1
194387
1
193664
1
192736
1
192921
1
193028
1
192631
1
191908
1
191240
1
191235
1
190981
1
190925
1
189943
1
190198
1
189418
1
188763
1
189155
1
188672
1
189280
1
188610
1
187734
1
188041
1
187771
1
187854
1
187673
1
186410
1
187064
1
187512
1
187572
1
187523
1
185977
1
185768
1
186863
1
186480
1
186451
1
186329
1
186093
1
186564
1
185951
1
186190
1
185733
1
186264
1
186215
1
185820
1
186163
1
185258
1
185859
1
186007
1
186050
1
185850
1
185878
1
185342
1
185219
1
186149
1
185495
1
185392
1
186011
1
185586
1
185278
1
185651
1
185634
1
185951
1
185486
1
185359
1
186267
1
186201
1
185914
1
185105
1
185191
1
185831
1
185727
1
186117
1
185594
1
185863
1
185874
1
185961
1
186084
1
185666
1
186575
1
186581
1
185717
1
185508
1
185447
1
185886
1
186306
1
185771
1
185849
1
186077
1
186282
1
186845
1
187136
1
186421
1
186329
1
185669
1
185948
1
186618
1
186192
1
186034
1
186263
1
186796
1
186746
1
187266
1
187138
1
186465
1
186593
1
186748
1
186919
1
186842
1
188005
1
187405
1
186642
1
186779
1
187435
1
186401
1
187623
1
186590
1
187183
1
187378
1
187072
1
187227
1
186547
1
187334
1
187057
1
187445
1
187621
1
187036
1
187762
1
187814
1
187612
1
187648
1
188088
1
187508
1
187770
1
187452
1
187886
1
187834
1
187881
1
188083
1
187280
1
188058
1
188423
1
187887
1
188729
1
188141
1
187654
1
188464
1
188839
1
187959
1
187777
1
188281
1
188489
1
187924
1
188016
1
188249
1
188563
1
188411
1
188219
1
188579
1
188560
1
188746
1
188473
1
188299
1
188048
1
188542
1
188735
1
189084
1
188688
1
188825
1
188354
1
188531
1
188709
1
188233
1
188295
1
188641
1
188786
1
188853
1
188927
1
188296
1
187999
1
188531
1
188500
1
188561
1
188803
1
189216
1
188103
1
187991
1
188062
1
188678
1
188980
1
188782
1
188988
1
189405
1
189204
1
187990
1
188123
1
188716
1
188864
1
188461
1
188323
1
188716
1
188962
1
189055
1
188861
1
188974
1
189294
1
188379
1
189048
1
188916
1
188371
1
188802
1
188659
1
188880
1
188400
1
188810
1
188618
1
188900
1
189083
1
189400
1
188880
1
188758
1
188920
1
189444
1
189468
1
189808
1
189705
1
189343
1
188795
1
188881
1
189060
1
189090
1
189018
1
188461
1
188922
1
189023
1
189670
1
188868
1
189210
1
189023
1
189686
1
190017
1
189300
1
189384
1
189117
1
189197
1
189553
1
189163
1
189166
1
188932
1
189342
1
188884
1
189165
1
189365
1
189294
1
189285
1
189655
1
189532
1
189710
1
189149
1
189600
1
189881
1
189220
1
189624
1
189258
1
190062
1
190290
1
190082
1
190521
1
189790
1
190247
1
190080
1
189760
1
190241
1
190042
1
Cu LMM
PK_Cu_AES
2020
2
20
13
31
23
1
42
Casa Info Follows
0
0
0
0
Creation
Created by : DESKTOP-MI6NA2R\kratos
Date created : 20/02/2020 13:31
Computer : DESKTOP-MI6NA2R
Location
Location ID : 1: PK_Cu_AES
Sample : PK_Cu_AES
Description : (43.434,6.505,-2.973)mm
Tilt : 0.00
Charge Neutraliser : Off
Settings
Excitation
Mode : FEG Electron Gun
Tuning : 10 keV
Spot size : 0
Anode library : AES
ESCA modes
Collimation : AES
Lens : AES
Resolution : 3.00
Scan
Deflection : (0.000, 0.000)mm
Cu LMM : 750.000-950.000eV, Sweeps 5
Start : 750.000eV
End : 950.000eV
Centre : 850.000eV
Width : 200.000eV
Step size : 0.200eV
Number Steps : 1000
Dwell time : 180ms
Sweep time : 180s
Sweeps : 5
Target quality : 200
Instrument Conditions
Work function : -4.50
Acquisition Conditions
Quality : 187.02
XPS
4
43.434
6.50523
-2.9731
Not specified
0
1e+037
1e+037
1e+037
1e+037
1e+037
FAT
3
1e+037
-4.5
1e+037
1e+037
1e+037
1e+037
1e+037
Cu
LMM
-1
Kinetic energy
eV
750
0.2
2
Intensity
d
Transmission
d
pulse counting
0.17982
0
1e+037
0
118118
1
150383
150179
150063
150344
150788
149962
150515
150781
150726
150157
150779
150800
151345
150649
150700
150645
151075
150759
151469
151349
151864
151668
151411
151534
151475
151541
151513
152147
151925
151416
151440
152171
152406
152753
152814
151753
152016
152415
152335
152724
152973
153303
152655
152268
152400
152533
152267
152082
152866
152519
153090
152358
152869
153597
154009
153593
153728
153165
153306
153796
153765
154197
153681
153737
153723
153685
154761
154916
154557
155282
155374
154890
153928
154565
154307
154816
154866
154809
154795
155497
155349
155256
155519
155672
155625
155197
155154
154735
154959
154840
154129
154792
155832
154610
154824
154646
154339
154436
154670
154185
153869
154187
154061
153195
154005
154270
153599
154127
154145
154103
153660
153932
153358
153065
153433
153591
153030
153264
153832
153485
153037
153299
152239
152654
153064
152436
151828
151849
151206
150962
150822
150213
149901
150051
149882
149435
149103
149143
148516
148211
148653
148084
147735
147599
147449
146862
147173
147172
146668
146426
146167
146822
146634
146750
147040
146118
145792
146128
145967
145894
146051
146041
145682
146290
145906
145947
145890
146070
146028
146268
146216
145594
145650
145395
145976
145941
145812
146320
145521
145186
146459
146020
145898
145660
145680
145819
146104
145866
146461
146112
146400
145892
145955
146079
145485
145689
145470
145425
145334
145345
145463
146103
145762
145584
145963
145792
145962
145596
145422
146054
145711
145187
145454
145950
145404
145639
145868
145832
146290
146099
145494
145805
146392
145599
145714
145424
146108
145133
145370
145702
145355
145739
146279
145929
145741
145832
145679
145575
145579
145916
145421
145657
145475
145586
145240
145008
144977
144851
145084
144833
144913
144794
145775
144724
144533
144157
144685
144598
145056
145213
145214
144809
144372
145482
144847
144564
144367
145155
144750
144925
144824
144917
144951
144824
144757
144854
145772
145482
145198
144700
145230
145792
145788
145613
145766
145362
145718
145947
146137
145860
145833
146185
146444
146308
146791
146275
146094
146074
145879
146258
146594
147053
146900
147030
147072
146268
146701
146549
146996
147051
147198
147183
146906
146659
147142
147016
147774
147068
147491
147430
147585
146923
147054
147226
147029
147743
147198
147447
147583
147734
147500
148063
148127
147416
147549
147844
148055
148561
148817
148945
148492
148382
149160
148670
148650
148670
148260
148283
149140
148438
148751
148839
148709
149207
149396
148882
149210
149305
148704
149312
149277
148875
149301
149474
149285
148759
149373
149119
149661
149935
149518
149293
149521
149672
150376
150097
150495
150499
150409
150456
150688
150690
151089
150773
151274
151238
151129
151192
151662
151912
151984
151616
152195
151918
151877
152467
152395
151935
152478
152837
153068
152951
153779
153318
153836
153604
153243
153515
153751
153762
153469
153848
153451
153877
153965
154114
154247
154857
154492
154331
154185
154617
154712
154550
155053
155858
155151
155024
155991
156707
157075
157502
158033
157910
158446
158241
158558
158952
159472
159167
158814
158739
158540
158063
158147
158198
157643
157079
156712
156412
155519
155484
154705
153894
153954
152835
153172
152449
151662
151547
151249
150875
151118
151469
151209
150937
151159
149898
150074
150321
150016
150263
150924
150343
151069
150896
150850
150983
151002
151057
150572
150296
150826
150471
149760
149772
149529
149217
148248
148437
147850
147669
147018
147246
146451
145750
145491
145732
145353
144916
144404
144299
143492
143342
142883
143399
142363
142959
142192
141968
142263
142162
141680
141539
141463
141290
140787
140446
140245
140116
140665
140608
141027
140692
140627
140832
140880
140231
140427
140125
140389
139774
140293
140530
140270
139904
140258
140366
139968
140338
140027
139340
139538
139793
139891
139556
139640
139351
138989
139191
138464
138503
138627
138176
137829
137477
137828
138039
138556
137812
137320
137491
138429
137577
137624
137144
137218
137142
137435
137360
137237
136913
136836
136644
137159
137207
136619
137406
137246
136438
136638
136881
136884
136479
136137
136259
136430
136459
135949
135887
135749
135876
136336
135891
135638
135133
135955
135467
136011
135768
135518
135576
135721
135806
136021
136578
135771
135857
135493
135782
135420
135683
135857
135938
135151
135941
136092
136188
136410
136475
136254
136283
136298
135387
135917
136079
135997
136402
136383
136364
136447
135790
136406
136556
136124
135832
136368
136319
136629
136431
136500
136864
136774
136284
136453
136487
136449
136534
136502
137017
137227
136902
137309
137222
137040
136943
137404
137860
137558
137229
137690
136955
137243
138136
137455
137684
137948
137197
137165
137634
137559
137804
137879
137909
137516
138191
138345
138246
138247
138595
138140
138504
139146
139242
139192
138840
138804
138645
139069
138927
139077
139530
139543
139421
139022
138908
139757
140256
139494
138990
139805
139727
139228
139631
139971
139715
140397
140337
139640
140174
140036
140155
140341
140270
140334
140673
140498
140504
140666
140244
140738
140917
140487
140746
140303
140954
140566
140835
140765
141496
140688
141310
140566
141201
141682
141396
140946
141385
141347
140681
141037
141146
141014
141272
141423
140614
141007
140931
141271
141875
141688
141330
141699
141661
141653
141710
141622
141742
141778
141380
141599
141806
142389
142602
142022
142178
142133
142460
142479
142586
142801
142772
142575
142943
143215
143248
143286
143414
143652
143843
144026
144542
144190
144253
144397
144440
145221
144841
144750
145060
145738
145512
146152
146507
146435
146601
146701
146928
147308
147238
148108
148084
148332
148448
149113
149327
149961
149867
150439
150782
151538
151694
152337
152645
153506
153882
153957
154774
155926
155456
156738
157231
158126
158146
158667
159601
159611
159916
161370
162381
163398
165331
166164
166405
166507
166194
166532
165950
165397
164829
164893
163126
162113
161984
160956
160308
159523
158703
156786
155184
153543
150603
147879
145477
143982
141962
140702
139671
138321
137820
137153
136375
135747
134933
133722
133231
132355
131789
131403
130852
130650
130239
130872
130538
130031
130057
129590
129181
129453
128930
129690
129344
128445
128310
128363
128485
128284
127717
127960
128023
127431
126655
127224
127327
126862
126689
127160
127089
126475
126637
126868
126111
126634
126758
126740
126616
125861
126565
126925
126515
127416
127580
127403
126994
127401
126824
126852
127053
127060
127173
127109
127395
127271
127292
127238
126672
127006
127145
126620
127358
127134
126969
126872
126987
126919
126983
126608
126084
126120
126507
126076
125793
125761
125830
125659
125582
125441
124455
124502
123943
123600
123885
122665
122237
121823
121677
121983
120941
121092
120273
120585
120341
120959
120341
119966
119991
119847
119736
119759
119706
119309
119516
119421
119203
119511
119944
119360
119433
119547
119521
119161
118722
119093
119012
119180
118685
118873
118683
118976
118985
119139
119048
118527
118710
118771
118754
118315
118118
118629
118879
118694
1
end of experiment