File: testFiles/multiplex.vms
VAMAS Surface Chemical Analysis Standard Data Transfer Format 1988 May 4
Not specified
MI-600-BE9240AA
DESKTOP-MI6NA2R\kratos
20200210_TaO2_AC_test.experiment
0
NORM
REGULAR
1
4
Index
d
PositionX [mm]
n
PositionY [mm]
n
PositionZ [mm]
n
0
0
0
0
3
wide
Ta
2020
2
10
10
22
38
1
36
Creation
Created by : DESKTOP-MI6NA2R\kratos
Date created : 10/02/2020 10:22
Computer : DESKTOP-MI6NA2R
Location
Location ID : Ta
Sample : Ta
Description : (55.796,2.896,-0.800)mm
Tilt : 0.00
Charge Neutraliser : Off
Settings
Excitation
Mode : XPS - monochromatic
Tuning : Spectroscopy
Emission current : 15.00mA
Anode library : Al
ESCA modes
Collimation : Slot
Lens : Hybrid
Resolution : 160.00
Scan
Deflection : (0.000, 0.000)mm
wide : 286.690-1491.690eV, Sweeps 2
Start : 286.690eV
End : 1491.690eV
Centre : 889.190eV
Width : 1205.000eV
Step size : 1.000eV
Number Steps : 1205
Dwell time : 100ms
Sweep time : 120s
Sweeps : 2
Instrument Conditions
Work function : -4.50
Acquisition Conditions
X-ray Power : 225.00W
XPS
1
55.7963036326509
2.89567917788632
-0.8
Al (mono)
1486.69
225
1E+37
1E+37
1E+37
1E+37
FAT
160
1E+37
-4.5
1E+37
1E+37
1E+37
1E+37
1E+37
wide

-1
Kinetic energy
eV
286.69
1
2
Intensity
d
Transmission
d
pulse counting
0.099502
0
1E+37
0
15
12.1974630554708
65292
65707
65935
65710
65610
65678
65462
65773
65301
65953
65365
64889
65346
65215
64825
64983
65253
64890
65713
64907
64878
64815
64773
64449
63690
64080
64299
64351
64192
64335
64071
63870
64357
64537
64768
64980
64642
64477
64532
64638
64840
64708
65055
65206
65132
65112
65258
65310
65564
65920
65767
65505
65303
65250
64895
64433
63816
63025
62451
61964
61677
61850
61174
61024
60666
60696
60467
60506
60575
60165
60315
60151
60125
60385
59983
59947
60036
59765
59740
60142
59891
59748
59864
59746
59813
60156
60100
59848
59758
59792
59875
59329
59123
59571
59638
59527
59376
59562
59827
59738
59690
59618
59628
59384
59449
59863
59487
59107
59126
59473
59111
59276
59559
59033
58986
58693
59132
59233
58753
58560
58411
58482
58240
58256
57942
57966
57792
58159
58060
57725
58015
57966
57894
57572
57687
57759
57950
57858
57749
57705
57613
57941
57894
57534
58093
57826
58154
58045
58044
58136
58433
57989
57661
57908
57986
58212
57694
57723
57820
57995
58022
58441
58297
58103
57924
58215
57919
58037
58097
58300
58016
58533
58593
58686
58327
58206
58423
58100
58552
58613
58334
58550
58359
58557
58948
58933
58811
59031
59605
59891
59971
60036
60343
59681
59538
58998
58518
58780
58859
59817
60171
60606
61549
62230
63770
64559
64045
62391
61022
59697
59380
58963
58698
58047
57536
56644
56449
56327
57033
58461
60750
64982
70291
76250
80562
80863
75074
67129
61410
57726
55084
53417
52172
50388
49262
47931
47731
47027
46650
46250
46133
45659
45287
45449
45255
45242
45595
45171
45200
45353
45417
45147
45040
44926
45183
45001
44758
44982
44960
45152
45030
45131
45385
45066
44944
44944
44902
44950
44924
45001
44961
44701
44790
44909
44921
44565
44773
45064
44703
44936
44819
45041
45195
45034
44816
44611
44525
44673
45042
44882
44628
44521
44943
45347
44918
44738
45228
45073
44860
44741
44869
44676
44897
45208
44848
44661
45079
44851
44735
45077
44664
44869
45086
44754
44957
44777
44890
45087
45142
44913
44760
44800
44858
44776
44733
44859
44777
44935
44980
45047
44829
44930
45006
45131
45165
45206
44747
44836
45117
45304
45111
45086
45345
45056
44874
44814
44911
44910
44967
45276
45160
44984
45177
44966
45118
45367
45333
45063
45281
45059
45120
44823
45140
45332
45265
45367
45478
45085
45072
45168
45126
45384
45190
44933
45272
45087
45263
45468
45230
44870
45146
45553
45257
45225
45205
45291
45294
45440
45337
45532
45231
45186
45432
45673
45594
45377
45666
45506
45398
45561
45696
45486
45449
45354
45752
45484
45311
45165
45515
45681
46067
46078
45689
45601
45762
45957
45850
45701
45861
45664
45654
45880
46222
45908
45937
45972
46049
46043
45642
45966
46183
46250
45888
45541
45887
46016
46218
46162
46209
46400
46269
46047
46351
46277
46294
46287
46336
46293
46448
46230
46213
46282
46341
46311
46251
46208
46853
46589
46481
46522
46638
46499
46684
46763
46726
46517
46562
46653
46925
46734
46937
46561
47052
47043
46871
47203
47082
46998
47139
47043
46910
47354
47336
47327
47427
47501
46877
47094
47585
47132
47261
47173
47023
47331
47659
47347
47287
47469
47407
47400
47614
47520
47249
47162
47793
47940
47602
47625
48023
47885
47861
48195
47898
47558
47911
47764
47937
48076
48120
48011
47801
48192
48294
48246
48243
48582
48407
48332
48519
48305
48237
48554
48708
48733
48762
48511
48627
48683
48503
48803
48715
48998
48858
48835
49037
49136
49295
49420
49156
49154
49318
49105
49384
49284
49282
49594
49186
49514
49851
49501
49618
49309
49704
49651
49875
49700
49825
49923
50350
49885
50063
49900
50422
50267
50194
50482
50596
50662
50556
50659
50726
50590
50766
50860
51085
50418
50267
50534
50993
50741
51218
51266
51025
51263
51188
51459
51561
51612
51522
51588
51532
51622
51860
51851
51994
52284
52058
52289
52577
52543
52603
52895
52937
53565
53629
53541
53447
53524
54594
53865
53701
53756
54031
53726
53723
54025
54718
54705
55350
56079
56730
57583
58090
58547
58613
57938
57483
56860
55700
54479
53796
53108
52454
52297
51746
51554
51776
51617
51668
51813
51591
51269
51295
51551
51225
50236
48897
47932
47565
46684
46299
46543
46007
46385
47035
48461
53204
65999
97669
119093
89259
53006
43156
42085
41464
41392
41067
41234
41310
40963
40932
40994
40825
40862
41161
40855
40919
40949
41007
41057
41210
41091
41283
41166
41043
41527
41614
41443
41155
41573
41821
41721
41844
42100
42074
42095
42230
42338
42328
42784
42709
42855
42954
42904
42814
43240
43356
43625
43586
43725
43678
43728
43444
43828
44076
44185
44304
44857
45700
46237
47251
48341
49604
50323
50768
50448
49933
48843
47678
46417
45093
44206
43419
43103
42499
42056
41676
41179
40961
41110
40968
40907
40786
40710
40518
40608
40907
40806
40869
40864
40897
41207
40897
41408
41755
41616
41656
41899
42168
42210
42427
42675
43043
43043
43143
43601
43670
44086
44024
44338
44285
44432
44457
44410
44256
44337
44810
45212
45684
46715
47954
50424
53216
57130
60887
63544
64710
63605
61046
57728
53123
48504
44711
41736
39892
38121
37103
36343
35581
35199
34898
34683
34565
34419
34342
33963
33915
34042
34216
34061
34035
33822
33899
34100
33898
34027
34007
33986
33983
34019
34090
34323
34204
34212
33973
34336
34180
34348
34479
34393
34331
34521
34424
34613
34556
34720
34780
34715
35023
35022
35155
35469
35679
35638
35737
35542
35636
35458
35404
35417
35844
35734
35696
36225
36558
36164
36432
36374
36576
36266
36606
36580
36349
36836
36921
36945
36987
37191
37716
38188
38746
38489
38122
38231
38300
37940
37990
38270
38357
38499
38678
38517
38569
39036
39027
38520
38963
39275
39354
39398
39227
39804
39896
40425
40370
40513
40684
40743
40839
41149
41432
41670
42351
42487
43344
43753
43738
43811
43391
43007
42556
42160
42148
42076
42681
42735
43126
43297
43655
43875
44466
44740
44971
45107
45513
45935
46662
46876
47571
48106
48921
49716
50104
50294
50725
51074
50731
50809
51146
51556
52726
53950
56091
58699
62137
67862
75651
83870
88875
88349
83083
78155
72031
64867
59412
57915
60321
67298
78009
87789
89827
86057
79555
70536
58920
46229
36072
29160
25032
22544
20551
19110
18331
17639
17006
16455
16117
15851
15625
15460
15264
15205
15418
14908
14855
14685
14811
14752
14405
14478
14476
14584
14386
14575
14384
14302
14385
14285
14290
14418
14302
14197
14323
14449
14569
14740
14586
14394
14527
14459
14362
14510
14552
14567
14443
14665
14601
14592
14697
14738
14758
14692
14745
14761
14846
15046
15074
14995
14973
14939
14976
14941
15040
15265
15406
15267
15344
15431
15241
15451
15354
15711
15561
15721
15534
15702
15890
15858
15825
15791
15974
15913
15885
15990
16265
16132
16133
16330
16317
16392
16416
16615
16587
16582
16501
16820
16799
16861
17048
17068
17099
17077
17100
17299
17321
17292
17470
17555
17313
17504
17663
17782
17721
17969
18051
18073
18269
18296
18450
18391
18761
18726
18871
18919
18869
18956
19155
19345
19343
19433
19583
19563
19606
19675
20009
20017
20077
20545
20859
20665
20926
21264
21394
21631
21768
21854
22577
22792
22916
22588
22181
21938
21529
21051
20690
20644
20222
20117
20307
20574
20973
21256
21775
22304
22489
23088
23450
23823
24089
24285
24971
25542
26536
27926
29421
30079
30563
30029
29337
28271
27362
28090
30123
29871
28297
26857
25630
24141
22938
25264
38131
65744
86472
101415
97191
78989
67404
54384
35654
14898
4191
2109
1483
1159
1001
951
896
906
1017
1409
2453
3728
4250
4080
3762
3093
2166
1964
2493
2506
1443
409
65
31
19
15
15.5208295946116
2: O 1s
Ta
2020
2
10
10
42
32
1
36
Creation
Created by : DESKTOP-MI6NA2R\kratos
Date created : 10/02/2020 10:42
Computer : DESKTOP-MI6NA2R
Location
Location ID : Ta
Sample : Ta
Description : (55.796,2.896,-0.800)mm
Tilt : 0.00
Charge Neutraliser : Off
Settings
Excitation
Mode : XPS - monochromatic
Tuning : Spectroscopy
Emission current : 15.00mA
Anode library : Al
ESCA modes
Collimation : Slot
Lens : Hybrid
Resolution : 20.00
Scan
Deflection : (0.000, 0.000)mm
O 1s : 943.690-961.690eV, Sweeps 4
Start : 943.690eV
End : 961.690eV
Centre : 952.690eV
Width : 18.000eV
Step size : 0.200eV
Number Steps : 90
Dwell time : 659ms
Sweep time : 60s
Sweeps : 4
Instrument Conditions
Work function : -4.50
Acquisition Conditions
X-ray Power : 225.00W
XPS
2
55.7963036326509
2.89567917788632
-0.8
Al (mono)
1486.69
225
1E+37
1E+37
1E+37
1E+37
FAT
20
1E+37
-4.5
1E+37
1E+37
1E+37
1E+37
1E+37
O
1s
-1
Kinetic energy
eV
943.69
0.2
2
Intensity
d
Transmission
d
pulse counting
0.659341
4
0
1E+37
1E+37
1E+37
0
182
19746
80673
0.694879764806946
0.695782442442153
22606
0.694879764806946
22432
0.694889794558448
22128
0.694899824309951
22405
0.694909854061453
22255
0.694919883812955
22298
0.694929913564458
22232
0.69493994331596
22205
0.694949973067462
22082
0.694960002818964
22253
0.694970032570467
22310
0.694980062321969
21808
0.694990092073471
22037
0.695000121824974
22349
0.695010151576476
22285
0.695020181327978
22051
0.695030211079481
22103
0.695040240830983
22235
0.695050270582485
21979
0.695060300333987
22112
0.69507033008549
21878
0.695080359836992
21690
0.695090389588494
21636
0.695100419339997
21671
0.695110449091499
21599
0.695120478843001
21677
0.695130508594504
21744
0.695140538346006
21699
0.695150568097508
21569
0.695160597849011
21542
0.695170627600513
21384
0.695180657352015
21490
0.695190687103517
21406
0.69520071685502
21398
0.695210746606522
21273
0.695220776358024
21334
0.695230806109527
21587
0.695240835861029
21501
0.695250865612531
21763
0.695260895364034
21906
0.695270925115536
22347
0.695280954867038
22449
0.69529098461854
22668
0.695301014370043
23095
0.695311044121545
23402
0.695321073873047
23958
0.69533110362455
24491
0.695341133376052
24718
0.695351163127554
25585
0.695361192879057
26525
0.695371222630559
27690
0.695381252382061
29725
0.695391282133563
32421
0.695401311885066
37302
0.695411341636568
43985
0.69542137138807
54158
0.695431401139573
65118
0.695441430891075
74895
0.695451460642577
80673
0.69546149039408
79089
0.695471520145582
71138
0.695481549897084
59330
0.695491579648587
46424
0.695501609400089
36277
0.695511639151591
29138
0.695521668903093
24901
0.695531698654596
22476
0.695541728406098
21418
0.6955517581576
20825
0.695561787909103
20274
0.695571817660605
20508
0.695581847412107
20357
0.69559187716361
20177
0.695601906915112
20253
0.695611936666614
20290
0.695621966418116
20256
0.695631996169619
20106
0.695642025921121
19991
0.695652055672623
20191
0.695662085424126
20149
0.695672115175628
20030
0.69568214492713
20015
0.695692174678633
20012
0.695702204430135
20057
0.695712234181637
20154
0.69572226393314
20150
0.695732293684642
19848
0.695742323436144
19746
0.695752353187646
19843
0.695762382939149
20113
0.695772412690651
19926
0.695782442442153
2: Ta 4f
Ta
2020
2
10
10
42
32
1
36
Creation
Created by : DESKTOP-MI6NA2R\kratos
Date created : 10/02/2020 10:42
Computer : DESKTOP-MI6NA2R
Location
Location ID : Ta
Sample : Ta
Description : (55.796,2.896,-0.800)mm
Tilt : 0.00
Charge Neutraliser : Off
Settings
Excitation
Mode : XPS - monochromatic
Tuning : Spectroscopy
Emission current : 15.00mA
Anode library : Al
ESCA modes
Collimation : Slot
Lens : Hybrid
Resolution : 20.00
Scan
Deflection : (0.000, 0.000)mm
Ta 4f : 1451.690-1469.690eV, Sweeps 4
Start : 1451.690eV
End : 1469.690eV
Centre : 1460.690eV
Width : 18.000eV
Step size : 0.200eV
Number Steps : 90
Dwell time : 659ms
Sweep time : 60s
Sweeps : 4
Instrument Conditions
Work function : -4.50
Acquisition Conditions
X-ray Power : 225.00W
XPS
3
55.7963036326509
2.89567917788632
-0.8
Al (mono)
1486.69
225
1E+37
1E+37
1E+37
1E+37
FAT
20
1E+37
-4.5
1E+37
1E+37
1E+37
1E+37
1E+37
Ta
4f
-1
Kinetic energy
eV
1451.69
0.2
2
Intensity
d
Transmission
d
pulse counting
0.659341
4
0
1E+37
1E+37
1E+37
0
182
498
64947
0.679050640006433
0.681483452347408
11842
0.679050640006433
11695
0.679077671254666
11484
0.679104702502899
11720
0.679131733751132
11490
0.679158764999365
11282
0.679185796247598
10995
0.679212827495831
10782
0.679239858744064
10584
0.679266889992297
10289
0.67929392124053
10088
0.679320952488763
9479
0.679347983736996
9190
0.679375014985229
8869
0.679402046233462
8853
0.679429077481696
8821
0.679456108729929
8783
0.679483139978162
8888
0.679510171226395
8962
0.679537202474628
9255
0.679564233722861
9740
0.679591264971094
10044
0.679618296219327
10426
0.67964532746756
11470
0.679672358715793
13001
0.679699389964026
15529
0.679726421212259
19678
0.679753452460492
25181
0.679780483708725
32835
0.679807514956958
40318
0.679834546205191
45946
0.679861577453425
46670
0.679888608701658
43431
0.679915639949891
38873
0.679942671198124
35604
0.679969702446357
35122
0.67999673369459
38675
0.680023764942823
45499
0.680050796191056
54259
0.680077827439289
61283
0.680104858687522
64947
0.680131889935755
62192
0.680158921183988
55685
0.680185952432221
48118
0.680212983680454
42677
0.680240014928687
38586
0.680267046176921
35838
0.680294077425154
33866
0.680321108673387
32679
0.68034813992162
33032
0.680375171169853
33905
0.680402202418086
35268
0.680429233666319
36902
0.680456264914552
36927
0.680483296162785
35335
0.680510327411018
31624
0.680537358659251
27072
0.680564389907484
23833
0.680591421155717
22581
0.68061845240395
22790
0.680645483652183
23908
0.680672514900416
24912
0.68069954614865
25054
0.680726577396883
22539
0.680753608645116
17986
0.680780639893349
12506
0.680807671141582
7303
0.680834702389815
4031
0.680861733638048
2369
0.680888764886281
1838
0.680915796134514
1643
0.680942827382747
1333
0.68096985863098
1251
0.680996889879213
1109
0.681023921127446
1037
0.681050952375679
932
0.681077983623912
856
0.681105014872146
766
0.681132046120379
751
0.681159077368612
739
0.681186108616845
665
0.681213139865078
662
0.681240171113311
605
0.681267202361544
558
0.681294233609777
576
0.68132126485801
555
0.681348296106243
513
0.681375327354476
522
0.681402358602709
540
0.681429389850942
498
0.681456421099175
509
0.681483452347408
end of experiment